2023-06-13 09:44:58,896 - ERROR - An unexpected error occurred: name 'localhost' is not defined
Traceback (most recent call last):
  File "/Workshop/challenge_2/node-RED_MQTT.py", line 91, in <module>
    client.connect(localhost, 1883, 60)
NameError: name 'localhost' is not defined
2023-06-13 09:45:43,489 - ERROR - An unexpected error occurred: name 'host' is not defined
Traceback (most recent call last):
  File "/Workshop/challenge_2/node-RED_MQTT.py", line 91, in <module>
    client.connect(host, 1883, 60)
NameError: name 'host' is not defined
2023-06-13 10:27:11,443 - ERROR - An unexpected error occurred: name 'mqtt_broker' is not defined
Traceback (most recent call last):
  File "/Workshop/challenge_2/node-RED_MQTT.py", line 91, in <module>
    client.loop_forever()
  File "/usr/local/lib/python3.9/dist-packages/paho/mqtt/client.py", line 1756, in loop_forever
    rc = self._loop(timeout)
  File "/usr/local/lib/python3.9/dist-packages/paho/mqtt/client.py", line 1164, in _loop
    rc = self.loop_read()
  File "/usr/local/lib/python3.9/dist-packages/paho/mqtt/client.py", line 1556, in loop_read
    rc = self._packet_read()
  File "/usr/local/lib/python3.9/dist-packages/paho/mqtt/client.py", line 2439, in _packet_read
    rc = self._packet_handle()
  File "/usr/local/lib/python3.9/dist-packages/paho/mqtt/client.py", line 3039, in _packet_handle
    return self._handle_connack()
  File "/usr/local/lib/python3.9/dist-packages/paho/mqtt/client.py", line 3138, in _handle_connack
    on_connect(
  File "/Workshop/challenge_2/node-RED_MQTT.py", line 64, in on_connect
    print("Verbunden mit dem MQTT-Broker: " + mqtt_broker)
NameError: name 'mqtt_broker' is not defined
2023-06-13 12:43:27,121 - ERROR - Serial communication error: device reports readiness to read but returned no data (device disconnected or multiple access on port?)
2023-06-13 12:44:01,313 - ERROR - Serial communication error: device reports readiness to read but returned no data (device disconnected or multiple access on port?)
2023-06-13 12:44:19,056 - ERROR - Serial communication error: device reports readiness to read but returned no data (device disconnected or multiple access on port?)
2023-06-13 13:01:29,800 - ERROR - An unexpected error occurred: name 'client' is not defined
Traceback (most recent call last):
  File "/Workshop/challenge_2/main1.py", line 115, in <module>
    client.publish_massage = publish_message(mqtt_temp, message_temp)
NameError: name 'client' is not defined
2023-06-13 17:40:13,744 - ERROR - An unexpected error occurred: name 'manual_vent' is not defined
Traceback (most recent call last):
  File "/Workshop/challenge_2/main_copy.py", line 143, in <module>
    vent_control(manual_vent)
NameError: name 'manual_vent' is not defined
2023-06-13 17:41:11,533 - ERROR - An unexpected error occurred: name 'manual_vent' is not defined
Traceback (most recent call last):
  File "/Workshop/challenge_2/main_copy.py", line 143, in <module>
    vent_control(manual_vent)
NameError: name 'manual_vent' is not defined
2023-06-13 17:44:49,339 - ERROR - An unexpected error occurred: name 'level_value' is not defined
Traceback (most recent call last):
  File "/Workshop/challenge_2/main_copy.py", line 143, in <module>
    print(f"KÃ¼hlung Stufe {level_value}")
NameError: name 'level_value' is not defined
2023-06-13 18:22:55,106 - ERROR - PostgreSQL database error: current transaction is aborted, commands ignored until end of transaction block

2023-06-13 18:32:08,587 - ERROR - PostgreSQL database error: relation "vent_stats" does not exist
LINE 1: SELECT MAX(vent_stat_id) FROM vent_stats
                                      ^

2023-06-13 18:58:54,129 - ERROR - PostgreSQL database error: duplicate key value violates unique constraint "event_pkey"
DETAIL:  Key (event_id)=(1) already exists.

2023-06-13 18:59:39,164 - ERROR - PostgreSQL database error: duplicate key value violates unique constraint "event_pkey"
DETAIL:  Key (event_id)=(1) already exists.

2023-06-16 11:36:54,077 - ERROR - PostgreSQL database error: could not connect to server: Connection timed out
	Is the server running on host "104.211.25.177" and accepting
	TCP/IP connections on port 6666?

2023-06-16 11:56:28,887 - ERROR - PostgreSQL database error: insert or update on table "reading" violates foreign key constraint "reading_sensor_id_fkey"
DETAIL:  Key (sensor_id)=(1) is not present in table "sensor".

